Workbook
Name Alexandria: SightseeingLists!$J$2:$J$19
Name ASW: TransportationLists!$T$4:$T$37
Name Aswan: SightseeingLists!$L$2:$L$19
Name CAI: TransportationLists!$V$4:$V$47
Name Cairo: SightseeingLists!$I$2:$I$29
Name Giza: SightseeingLists!$M$2:$M$17
Name HRG: TransportationLists!$R$4:$R$37
Name Luxor: SightseeingLists!$K$2:$K$40
Name LXR: TransportationLists!$S$4:$S$47
Name Names_SSH: TransportationLists!$C$4:$C$30
Name RMF: TransportationLists!$U$4:$U$27
Name SSH: TransportationLists!$Q$4:$Q$30
Name TRSF_Price: TransportationLists!$C$4:$N$220

Sheet Calculation Sheet
C1: No. Of Pax | E1: 2
C3: ROE | E3: 30.95
C5: Profit Margin | E5: 151.9
C7: Net PP $ | E7: =IFERROR(SUM(U18,BA18,U47),0) -> 311.63166 | G7: =IFERROR(SUM(E5:E7),0) -> 463.53166
C9: VAT % | E9: 0.21 | G9: =IFERROR(G7*(1+$E$9),0) -> 560.87331
C11: Selling PP inc. VAT | E11: =$G$9 -> 560.87331
C13: Including FOC | E13: =E11*16/15 -> 598.26487
C15: Transportation Calculation | AA15: Sightseeing Calculation
U16: Total Transfers PP
U18: =IFERROR(SUM($U22:$U40),0) -> 170.75929 | BA18: =IFERROR(SUM($BA22:$BA57),0) -> 140.87237
C20: Destination | E20: Transfer Name | G20: Transfer Slice | I20: Transfer Price | K20: Driver Tip | M20: Rep Tip | O20: # of TRSF | Q20: TTL TRSF | S20: Price PP EGP | U20: Price PP $ | AA20: Destination | AC20: Sightseeing | AE20: Price EGP | AG20: Guidance | AI20: Rep Tip | AK20: Police Tip | AM20: Police Permitt | AO20: Meals | AQ20: Drinks | AS20: Parking | AU20: TTL PP in EGP | AW20: G/PP | AY20: G.TTL PP EGP | BA20: Price USD
B22: i | C22: CAI | E22: مطار / سهرة من وسط البلد / هرم | G22: 1*11 | I22: =IFERROR(IF($G22=TransportationLists!$O$4,VLOOKUP($E22,TRSF_Price,2,FALSE),IF($G22=TransportationLists!$O$5,VLOOKUP($E22,TRSF_Price,4,FALSE),IF($G22=TransportationLists!$O$6,VLOOKUP($E22,TRSF_Price,6,FALSE),IF($G22=TransportationLists!$O$7,VLOOKUP($E22,TRSF_Price,8,FALSE),IF($G22=TransportationLists!$O$8,VLOOKUP($E22,TRSF_Price,10,FALSE)))))),0) -> 500 | K22: =IFERROR(IF($G22=TransportationLists!$O$4,VLOOKUP($E22,TRSF_Price,3,FALSE),IF($G22=TransportationLists!$O$5,VLOOKUP($E22,TRSF_Price,5,FALSE),IF($G22=TransportationLists!$O$6,VLOOKUP($E22,TRSF_Price,7,FALSE),IF($G22=TransportationLists!$O$7,VLOOKUP($E22,TRSF_Price,9,FALSE),IF($G22=TransportationLists!$O$8,VLOOKUP($E22,TRSF_Price,11,FALSE)))))),) -> 150 | M22: =IFERROR(IF($G22=TransportationLists!$O$4,VLOOKUP($E22,TRSF_Price,12,FALSE),IF($G22=TransportationLists!$O$5,VLOOKUP($E22,TRSF_Price,12,FALSE),IF($G22=TransportationLists!$O$6,VLOOKUP($E22,TRSF_Price,12,FALSE),IF($G22=TransportationLists!$O$7,VLOOKUP($E22,TRSF_Price,12,FALSE),IF($G22=TransportationLists!$O$8,VLOOKUP($E22,TRSF_Price,12,FALSE)))))),0) -> 250 | O22: 3 | Q22: =IFERROR(($I22+$K22+$M22)*$O22,0) -> 2700 | S22: =IFERROR($Q22/$E$1,0) -> 1350 | U22: =IFERROR($S22/$E$3,0) -> 43.61874 | Z22: i | AA22: Giza | AC22: منطقة أهرامات الجيزة | AE22: =IFERROR(VLOOKUP($AC22,SightseeingLists!$C$3:$E$121,2,FALSE),0) -> 540 | AG22: 1500 | AI22: =VLOOKUP($AC22,SightseeingLists!$C$3:$E$121,3,FALSE) -> 0 | AK22: 100 | AM22: 150 | AO22: 400 | AQ22: 0 | AS22: 50 | AU22: =SUM(AE22,AO22,AQ22) -> 940 | AW22: =SUM($AG22,$AI22,$AK22,$AM22,$AS22)/$E$1 -> 900 | AY22: =SUM($AU22,$AW22) -> 1840 | BA22: =IFERROR($AY22/$E$3,0) -> 59.450727
B24: i | C24: HRG | E24: مطار - سهل حشيش | G24: 1*11 | I24: =IFERROR(IF($G24=TransportationLists!$O$4,VLOOKUP($E24,TRSF_Price,2,FALSE),IF($G24=TransportationLists!$O$5,VLOOKUP($E24,TRSF_Price,4,FALSE),IF($G24=TransportationLists!$O$6,VLOOKUP($E24,TRSF_Price,6,FALSE),IF($G24=TransportationLists!$O$7,VLOOKUP($E24,TRSF_Price,8,FALSE),IF($G24=TransportationLists!$O$8,VLOOKUP($E24,TRSF_Price,10,FALSE)))))),0) -> 605 | K24: =IFERROR(IF($G24=TransportationLists!$O$4,VLOOKUP($E24,TRSF_Price,3,FALSE),IF($G24=TransportationLists!$O$5,VLOOKUP($E24,TRSF_Price,5,FALSE),IF($G24=TransportationLists!$O$6,VLOOKUP($E24,TRSF_Price,7,FALSE),IF($G24=TransportationLists!$O$7,VLOOKUP($E24,TRSF_Price,9,FALSE),IF($G24=TransportationLists!$O$8,VLOOKUP($E24,TRSF_Price,11,FALSE)))))),) -> 100 | M24: =IFERROR(IF($G24=TransportationLists!$O$4,VLOOKUP($E24,TRSF_Price,12,FALSE),IF($G24=TransportationLists!$O$5,VLOOKUP($E24,TRSF_Price,12,FALSE),IF($G24=TransportationLists!$O$6,VLOOKUP($E24,TRSF_Price,12,FALSE),IF($G24=TransportationLists!$O$7,VLOOKUP($E24,TRSF_Price,12,FALSE),IF($G24=TransportationLists!$O$8,VLOOKUP($E24,TRSF_Price,12,FALSE)))))),0) -> 150 | O24: 2 | Q24: =IFERROR(($I24+$K24+$M24)*$O24,0) -> 1710 | S24: =IFERROR($Q24/$E$1,0) -> 855 | U24: =IFERROR($S24/$E$3,0) -> 27.625202 | Z24: i | AA24: Giza | AC24: هرم زوسر المدرج من المدخل الجنوبي (سقارة) | AE24: =IFERROR(VLOOKUP($AC24,SightseeingLists!$C$3:$E$121,2,FALSE),0) -> 220 | AS24: 50 | AU24: =SUM(AE24,AO24,AQ24) -> 220 | AW24: =SUM($AG24,$AI24,$AK24,$AM24,$AS24)/$E$1 -> 25 | AY24: =SUM($AU24,$AW24) -> 245 | BA24: =IFERROR($AY24/$E$3,0) -> 7.9159935
B26: i | C26: CAI | E26: 1/2 يومية هرم أو بلد من وسط البلد | G26: 1*11 | I26: =IFERROR(IF($G26=TransportationLists!$O$4,VLOOKUP($E26,TRSF_Price,2,FALSE),IF($G26=TransportationLists!$O$5,VLOOKUP($E26,TRSF_Price,4,FALSE),IF($G26=TransportationLists!$O$6,VLOOKUP($E26,TRSF_Price,6,FALSE),IF($G26=TransportationLists!$O$7,VLOOKUP($E26,TRSF_Price,8,FALSE),IF($G26=TransportationLists!$O$8,VLOOKUP($E26,TRSF_Price,10,FALSE)))))),0) -> 1100 | K26: =IFERROR(IF($G26=TransportationLists!$O$4,VLOOKUP($E26,TRSF_Price,3,FALSE),IF($G26=TransportationLists!$O$5,VLOOKUP($E26,TRSF_Price,5,FALSE),IF($G26=TransportationLists!$O$6,VLOOKUP($E26,TRSF_Price,7,FALSE),IF($G26=TransportationLists!$O$7,VLOOKUP($E26,TRSF_Price,9,FALSE),IF($G26=TransportationLists!$O$8,VLOOKUP($E26,TRSF_Price,11,FALSE)))))),) -> 100 | M26: =IFERROR(IF($G26=TransportationLists!$O$4,VLOOKUP($E26,TRSF_Price,12,FALSE),IF($G26=TransportationLists!$O$5,VLOOKUP($E26,TRSF_Price,12,FALSE),IF($G26=TransportationLists!$O$6,VLOOKUP($E26,TRSF_Price,12,FALSE),IF($G26=TransportationLists!$O$7,VLOOKUP($E26,TRSF_Price,12,FALSE),IF($G26=TransportationLists!$O$8,VLOOKUP($E26,TRSF_Price,12,FALSE)))))),0) -> 150 | O26: 2 | Q26: =IFERROR(($I26+$K26+$M26)*$O26,0) -> 2700 | S26: =IFERROR($Q26/$E$1,0) -> 1350 | U26: =IFERROR($S26/$E$3,0) -> 43.61874 | Z26: i | AA26: Cairo | AC26: قلعة صلاح الدين الأيوبي | AE26: =IFERROR(VLOOKUP($AC26,SightseeingLists!$C$3:$E$121,2,FALSE),0) -> 450 | AG26: 1500 | AK26: 100 | AM26: 150 | AO26: 400 | AS26: 50 | AU26: =SUM(AE26,AO26,AQ26) -> 850 | AW26: =SUM($AG26,$AI26,$AK26,$AM26,$AS26)/$E$1 -> 900 | AY26: =SUM($AU26,$AW26) -> 1750 | BA26: =IFERROR($AY26/$E$3,0) -> 56.542811
B28: i | C28: CAI | E28: تشغيل مفتوح 10 ساعات | G28: 1*11 | I28: =IFERROR(IF($G28=TransportationLists!$O$4,VLOOKUP($E28,TRSF_Price,2,FALSE),IF($G28=TransportationLists!$O$5,VLOOKUP($E28,TRSF_Price,4,FALSE),IF($G28=TransportationLists!$O$6,VLOOKUP($E28,TRSF_Price,6,FALSE),IF($G28=TransportationLists!$O$7,VLOOKUP($E28,TRSF_Price,8,FALSE),IF($G28=TransportationLists!$O$8,VLOOKUP($E28,TRSF_Price,10,FALSE)))))),0) -> 1500 | K28: =IFERROR(IF($G28=TransportationLists!$O$4,VLOOKUP($E28,TRSF_Price,3,FALSE),IF($G28=TransportationLists!$O$5,VLOOKUP($E28,TRSF_Price,5,FALSE),IF($G28=TransportationLists!$O$6,VLOOKUP($E28,TRSF_Price,7,FALSE),IF($G28=TransportationLists!$O$7,VLOOKUP($E28,TRSF_Price,9,FALSE),IF($G28=TransportationLists!$O$8,VLOOKUP($E28,TRSF_Price,11,FALSE)))))),) -> 100 | M28: =IFERROR(IF($G28=TransportationLists!$O$4,VLOOKUP($E28,TRSF_Price,12,FALSE),IF($G28=TransportationLists!$O$5,VLOOKUP($E28,TRSF_Price,12,FALSE),IF($G28=TransportationLists!$O$6,VLOOKUP($E28,TRSF_Price,12,FALSE),IF($G28=TransportationLists!$O$7,VLOOKUP($E28,TRSF_Price,12,FALSE),IF($G28=TransportationLists!$O$8,VLOOKUP($E28,TRSF_Price,12,FALSE)))))),0) -> 150 | O28: 1 | Q28: =IFERROR(($I28+$K28+$M28)*$O28,0) -> 1750 | S28: =IFERROR($Q28/$E$1,0) -> 875 | U28: =IFERROR($S28/$E$3,0) -> 28.271405 | Z28: i | AA28: Cairo | AC28: المتحف المصري بالتحرير | AE28: =IFERROR(VLOOKUP($AC28,SightseeingLists!$C$3:$E$121,2,FALSE),0) -> 450 | AS28: 50 | AU28: =SUM(AE28,AO28,AQ28) -> 450 | AW28: =SUM($AG28,$AI28,$AK28,$AM28,$AS28)/$E$1 -> 25 | AY28: =SUM($AU28,$AW28) -> 475 | BA28: =IFERROR($AY28/$E$3,0) -> 15.347334
B30: i | C30: HRG | E30: مطار - سهل حشيش | G30: 1*11 | I30: =IFERROR(IF($G30=TransportationLists!$O$4,VLOOKUP($E30,TRSF_Price,2,FALSE),IF($G30=TransportationLists!$O$5,VLOOKUP($E30,TRSF_Price,4,FALSE),IF($G30=TransportationLists!$O$6,VLOOKUP($E30,TRSF_Price,6,FALSE),IF($G30=TransportationLists!$O$7,VLOOKUP($E30,TRSF_Price,8,FALSE),IF($G30=TransportationLists!$O$8,VLOOKUP($E30,TRSF_Price,10,FALSE)))))),0) -> 605 | K30: =IFERROR(IF($G30=TransportationLists!$O$4,VLOOKUP($E30,TRSF_Price,3,FALSE),IF($G30=TransportationLists!$O$5,VLOOKUP($E30,TRSF_Price,5,FALSE),IF($G30=TransportationLists!$O$6,VLOOKUP($E30,TRSF_Price,7,FALSE),IF($G30=TransportationLists!$O$7,VLOOKUP($E30,TRSF_Price,9,FALSE),IF($G30=TransportationLists!$O$8,VLOOKUP($E30,TRSF_Price,11,FALSE)))))),) -> 100 | M30: =IFERROR(IF($G30=TransportationLists!$O$4,VLOOKUP($E30,TRSF_Price,12,FALSE),IF($G30=TransportationLists!$O$5,VLOOKUP($E30,TRSF_Price,12,FALSE),IF($G30=TransportationLists!$O$6,VLOOKUP($E30,TRSF_Price,12,FALSE),IF($G30=TransportationLists!$O$7,VLOOKUP($E30,TRSF_Price,12,FALSE),IF($G30=TransportationLists!$O$8,VLOOKUP($E30,TRSF_Price,12,FALSE)))))),0) -> 150 | O30: 2 | Q30: =IFERROR(($I30+$K30+$M30)*$O30,0) -> 1710 | S30: =IFERROR($Q30/$E$1,0) -> 855 | U30: =IFERROR($S30/$E$3,0) -> 27.625202 | Z30: i | AA30: Cairo | AC30: المرشد السمعي ( المجموعات) التحف الصري | AE30: =IFERROR(VLOOKUP($AC30,SightseeingLists!$C$3:$E$121,2,FALSE),0) -> 50 | AU30: =SUM(AE30,AO30,AQ30) -> 50 | AW30: =SUM($AG30,$AI30,$AK30,$AM30,$AS30)/$E$1 -> 0 | AY30: =SUM($AU30,$AW30) -> 50 | BA30: =IFERROR($AY30/$E$3,0) -> 1.6155089
B32: i | I32: =IFERROR(IF($G32=TransportationLists!$O$4,VLOOKUP($E32,TRSF_Price,2,FALSE),IF($G32=TransportationLists!$O$5,VLOOKUP($E32,TRSF_Price,4,FALSE),IF($G32=TransportationLists!$O$6,VLOOKUP($E32,TRSF_Price,6,FALSE),IF($G32=TransportationLists!$O$7,VLOOKUP($E32,TRSF_Price,8,FALSE),IF($G32=TransportationLists!$O$8,VLOOKUP($E32,TRSF_Price,10,FALSE)))))),0) -> FALSE | K32: =IFERROR(IF($G32=TransportationLists!$O$4,VLOOKUP($E32,TRSF_Price,3,FALSE),IF($G32=TransportationLists!$O$5,VLOOKUP($E32,TRSF_Price,5,FALSE),IF($G32=TransportationLists!$O$6,VLOOKUP($E32,TRSF_Price,7,FALSE),IF($G32=TransportationLists!$O$7,VLOOKUP($E32,TRSF_Price,9,FALSE),IF($G32=TransportationLists!$O$8,VLOOKUP($E32,TRSF_Price,11,FALSE)))))),) -> FALSE | M32: =IFERROR(IF($G32=TransportationLists!$O$4,VLOOKUP($E32,TRSF_Price,12,FALSE),IF($G32=TransportationLists!$O$5,VLOOKUP($E32,TRSF_Price,12,FALSE),IF($G32=TransportationLists!$O$6,VLOOKUP($E32,TRSF_Price,12,FALSE),IF($G32=TransportationLists!$O$7,VLOOKUP($E32,TRSF_Price,12,FALSE),IF($G32=TransportationLists!$O$8,VLOOKUP($E32,TRSF_Price,12,FALSE)))))),0) -> FALSE | Q32: =IFERROR(($I32+$K32+$M32)*$O32,0) -> 0 | S32: =IFERROR($Q32/$E$1,0) -> 0 | U32: =IFERROR($S32/$E$3,0) -> 0 | Z32: i | AE32: =IFERROR(VLOOKUP($AC32,SightseeingLists!$C$3:$E$121,2,FALSE),0) -> 0 | AU32: =SUM(AE32,AO32,AQ32) -> 0 | AW32: =SUM($AG32,$AI32,$AK32,$AM32,$AS32)/$E$1 -> 0 | AY32: =SUM($AU32,$AW32) -> 0 | BA32: =IFERROR($AY32/$E$3,0) -> 0
B34: i | I34: =IFERROR(IF($G34=TransportationLists!$O$4,VLOOKUP($E34,TRSF_Price,2,FALSE),IF($G34=TransportationLists!$O$5,VLOOKUP($E34,TRSF_Price,4,FALSE),IF($G34=TransportationLists!$O$6,VLOOKUP($E34,TRSF_Price,6,FALSE),IF($G34=TransportationLists!$O$7,VLOOKUP($E34,TRSF_Price,8,FALSE),IF($G34=TransportationLists!$O$8,VLOOKUP($E34,TRSF_Price,10,FALSE)))))),0) -> FALSE | K34: =IFERROR(IF($G34=TransportationLists!$O$4,VLOOKUP($E34,TRSF_Price,3,FALSE),IF($G34=TransportationLists!$O$5,VLOOKUP($E34,TRSF_Price,5,FALSE),IF($G34=TransportationLists!$O$6,VLOOKUP($E34,TRSF_Price,7,FALSE),IF($G34=TransportationLists!$O$7,VLOOKUP($E34,TRSF_Price,9,FALSE),IF($G34=TransportationLists!$O$8,VLOOKUP($E34,TRSF_Price,11,FALSE)))))),) -> FALSE | M34: =IFERROR(IF($G34=TransportationLists!$O$4,VLOOKUP($E34,TRSF_Price,12,FALSE),IF($G34=TransportationLists!$O$5,VLOOKUP($E34,TRSF_Price,12,FALSE),IF($G34=TransportationLists!$O$6,VLOOKUP($E34,TRSF_Price,12,FALSE),IF($G34=TransportationLists!$O$7,VLOOKUP($E34,TRSF_Price,12,FALSE),IF($G34=TransportationLists!$O$8,VLOOKUP($E34,TRSF_Price,12,FALSE)))))),0) -> FALSE | Q34: =IFERROR(($I34+$K34+$M34)*$O34,0) -> 0 | S34: =IFERROR($Q34/$E$1,0) -> 0 | U34: =IFERROR($S34/$E$3,0) -> 0 | Z34: i | AE34: =IFERROR(VLOOKUP($AC34,SightseeingLists!$C$3:$E$121,2,FALSE),0) -> 0 | AU34: =SUM(AE34,AO34,AQ34) -> 0 | AW34: =SUM($AG34,$AI34,$AK34,$AM34,$AS34)/$E$1 -> 0 | AY34: =SUM($AU34,$AW34) -> 0 | BA34: =IFERROR($AY34/$E$3,0) -> 0
B36: i | I36: =IFERROR(IF($G36=TransportationLists!$O$4,VLOOKUP($E36,TRSF_Price,2,FALSE),IF($G36=TransportationLists!$O$5,VLOOKUP($E36,TRSF_Price,4,FALSE),IF($G36=TransportationLists!$O$6,VLOOKUP($E36,TRSF_Price,6,FALSE),IF($G36=TransportationLists!$O$7,VLOOKUP($E36,TRSF_Price,8,FALSE),IF($G36=TransportationLists!$O$8,VLOOKUP($E36,TRSF_Price,10,FALSE)))))),0) -> FALSE | K36: =IFERROR(IF($G36=TransportationLists!$O$4,VLOOKUP($E36,TRSF_Price,3,FALSE),IF($G36=TransportationLists!$O$5,VLOOKUP($E36,TRSF_Price,5,FALSE),IF($G36=TransportationLists!$O$6,VLOOKUP($E36,TRSF_Price,7,FALSE),IF($G36=TransportationLists!$O$7,VLOOKUP($E36,TRSF_Price,9,FALSE),IF($G36=TransportationLists!$O$8,VLOOKUP($E36,TRSF_Price,11,FALSE)))))),) -> FALSE | M36: =IFERROR(IF($G36=TransportationLists!$O$4,VLOOKUP($E36,TRSF_Price,12,FALSE),IF($G36=TransportationLists!$O$5,VLOOKUP($E36,TRSF_Price,12,FALSE),IF($G36=TransportationLists!$O$6,VLOOKUP($E36,TRSF_Price,12,FALSE),IF($G36=TransportationLists!$O$7,VLOOKUP($E36,TRSF_Price,12,FALSE),IF($G36=TransportationLists!$O$8,VLOOKUP($E36,TRSF_Price,12,FALSE)))))),0) -> FALSE | Q36: =IFERROR(($I36+$K36+$M36)*$O36,0) -> 0 | S36: =IFERROR($Q36/$E$1,0) -> 0 | U36: =IFERROR($S36/$E$3,0) -> 0 | Z36: i | AE36: =IFERROR(VLOOKUP($AC36,SightseeingLists!$C$3:$E$121,2,FALSE),0) -> 0 | AU36: =SUM(AE36,AO36,AQ36) -> 0 | AW36: =SUM($AG36,$AI36,$AK36,$AM36,$AS36)/$E$1 -> 0 | AY36: =SUM($AU36,$AW36) -> 0 | BA36: =IFERROR($AY36/$E$3,0) -> 0
B38: i | I38: =IFERROR(IF($G38=TransportationLists!$O$4,VLOOKUP($E38,TRSF_Price,2,FALSE),IF($G38=TransportationLists!$O$5,VLOOKUP($E38,TRSF_Price,4,FALSE),IF($G38=TransportationLists!$O$6,VLOOKUP($E38,TRSF_Price,6,FALSE),IF($G38=TransportationLists!$O$7,VLOOKUP($E38,TRSF_Price,8,FALSE),IF($G38=TransportationLists!$O$8,VLOOKUP($E38,TRSF_Price,10,FALSE)))))),0) -> FALSE | K38: =IFERROR(IF($G38=TransportationLists!$O$4,VLOOKUP($E38,TRSF_Price,3,FALSE),IF($G38=TransportationLists!$O$5,VLOOKUP($E38,TRSF_Price,5,FALSE),IF($G38=TransportationLists!$O$6,VLOOKUP($E38,TRSF_Price,7,FALSE),IF($G38=TransportationLists!$O$7,VLOOKUP($E38,TRSF_Price,9,FALSE),IF($G38=TransportationLists!$O$8,VLOOKUP($E38,TRSF_Price,11,FALSE)))))),) -> FALSE | M38: =IFERROR(IF($G38=TransportationLists!$O$4,VLOOKUP($E38,TRSF_Price,12,FALSE),IF($G38=TransportationLists!$O$5,VLOOKUP($E38,TRSF_Price,12,FALSE),IF($G38=TransportationLists!$O$6,VLOOKUP($E38,TRSF_Price,12,FALSE),IF($G38=TransportationLists!$O$7,VLOOKUP($E38,TRSF_Price,12,FALSE),IF($G38=TransportationLists!$O$8,VLOOKUP($E38,TRSF_Price,12,FALSE)))))),0) -> FALSE | Q38: =IFERROR(($I38+$K38+$M38)*$O38,0) -> 0 | S38: =IFERROR($Q38/$E$1,0) -> 0 | U38: =IFERROR($S38/$E$3,0) -> 0 | Z38: i | AE38: =IFERROR(VLOOKUP($AC38,SightseeingLists!$C$3:$E$121,2,FALSE),0) -> 0 | AU38: =SUM(AE38,AO38,AQ38) -> 0 | AW38: =SUM($AG38,$AI38,$AK38,$AM38,$AS38)/$E$1 -> 0 | AY38: =SUM($AU38,$AW38) -> 0 | BA38: =IFERROR($AY38/$E$3,0) -> 0
B40: i | I40: =IFERROR(IF($G40=TransportationLists!$O$4,VLOOKUP($E40,TRSF_Price,2,FALSE),IF($G40=TransportationLists!$O$5,VLOOKUP($E40,TRSF_Price,4,FALSE),IF($G40=TransportationLists!$O$6,VLOOKUP($E40,TRSF_Price,6,FALSE),IF($G40=TransportationLists!$O$7,VLOOKUP($E40,TRSF_Price,8,FALSE),IF($G40=TransportationLists!$O$8,VLOOKUP($E40,TRSF_Price,10,FALSE)))))),0) -> FALSE | K40: =IFERROR(IF($G40=TransportationLists!$O$4,VLOOKUP($E40,TRSF_Price,3,FALSE),IF($G40=TransportationLists!$O$5,VLOOKUP($E40,TRSF_Price,5,FALSE),IF($G40=TransportationLists!$O$6,VLOOKUP($E40,TRSF_Price,7,FALSE),IF($G40=TransportationLists!$O$7,VLOOKUP($E40,TRSF_Price,9,FALSE),IF($G40=TransportationLists!$O$8,VLOOKUP($E40,TRSF_Price,11,FALSE)))))),) -> FALSE | M40: =IFERROR(IF($G40=TransportationLists!$O$4,VLOOKUP($E40,TRSF_Price,12,FALSE),IF($G40=TransportationLists!$O$5,VLOOKUP($E40,TRSF_Price,12,FALSE),IF($G40=TransportationLists!$O$6,VLOOKUP($E40,TRSF_Price,12,FALSE),IF($G40=TransportationLists!$O$7,VLOOKUP($E40,TRSF_Price,12,FALSE),IF($G40=TransportationLists!$O$8,VLOOKUP($E40,TRSF_Price,12,FALSE)))))),0) -> FALSE | Q40: =IFERROR(($I40+$K40+$M40)*$O40,0) -> 0 | S40: =IFERROR($Q40/$E$1,0) -> 0 | U40: =IFERROR($S40/$E$3,0) -> 0 | Z40: i | AE40: =IFERROR(VLOOKUP($AC40,SightseeingLists!$C$3:$E$121,2,FALSE),0) -> 0 | AU40: =SUM(AE40,AO40,AQ40) -> 0 | AW40: =SUM($AG40,$AI40,$AK40,$AM40,$AS40)/$E$1 -> 0 | AY40: =SUM($AU40,$AW40) -> 0 | BA40: =IFERROR($AY40/$E$3,0) -> 0
B44: Accommodation Calculation | Z44: i | AE44: =IFERROR(VLOOKUP($AC44,SightseeingLists!$C$3:$E$121,2,FALSE),0) -> 0 | AU44: =SUM(AE44,AO44,AQ44) -> 0 | AW44: =SUM($AG44,$AI44,$AK44,$AM44,$AS44)/$E$1 -> 0 | AY44: =SUM($AU44,$AW44) -> 0 | BA44: =IFERROR($AY44/$E$3,0) -> 0
U45: Total Transfers PP | Z45: i | AE45: =IFERROR(VLOOKUP($AC45,SightseeingLists!$C$3:$E$121,2,FALSE),0) -> 0 | AU45: =SUM(AE45,AO45,AQ45) -> 0 | AW45: =SUM($AG45,$AI45,$AK45,$AM45,$AS45)/$E$1 -> 0 | AY45: =SUM($AU45,$AW45) -> 0 | BA45: =IFERROR($AY45/$E$3,0) -> 0
U47: =IFERROR(SUM($U51:$U71),0) -> 0 | Z47: i | AE47: =IFERROR(VLOOKUP($AC47,SightseeingLists!$C$3:$E$121,2,FALSE),0) -> 0 | AU47: =SUM(AE47,AO47,AQ47) -> 0 | AW47: =SUM($AG47,$AI47,$AK47,$AM47,$AS47)/$E$1 -> 0 | AY47: =SUM($AU47,$AW47) -> 0 | BA47: =IFERROR($AY47/$E$3,0) -> 0
C49: Room Occ | E49: Accommodation Name | G49: Arrival | I49: Departure | K49: Duration | M49: Rate PRPN | O49: Rooms | Q49: TTL Inc VAT | S49: TTL Ex VAT | Z49: i | AE49: =IFERROR(VLOOKUP($AC49,SightseeingLists!$C$3:$E$121,2,FALSE),0) -> 0 | AU49: =SUM(AE49,AO49,AQ49) -> 0 | AW49: =SUM($AG49,$AI49,$AK49,$AM49,$AS49)/$E$1 -> 0 | AY49: =SUM($AU49,$AW49) -> 0 | BA49: =IFERROR($AY49/$E$3,0) -> 0
D51: =IFERROR(IF(C51="DBL",2,IF(C51="SGL",1,IF(C51="TPL",3,0))),0) -> 0 | K51: =IFERROR(I51-G51,0) -> 0 | Q51: =IFERROR(K51*M51*O51,0) -> 0 | S51: =IFERROR(Q51/1.14,0) -> 0 | U51: =IFERROR((S51/D51),0) -> 0 | Z51: i | AE51: =IFERROR(VLOOKUP($AC51,SightseeingLists!$C$3:$E$121,2,FALSE),0) -> 0 | AU51: =SUM(AE51,AO51,AQ51) -> 0 | AW51: =SUM($AG51,$AI51,$AK51,$AM51,$AS51)/$E$1 -> 0 | AY51: =SUM($AU51,$AW51) -> 0 | BA51: =IFERROR($AY51/$E$3,0) -> 0
D53: =IFERROR(IF(C53="DBL",2,IF(C53="SGL",1,IF(C53="TPL",3,0))),0) -> 0 | K53: =IFERROR(I53-G53,0) -> 0 | Q53: =IFERROR(K53*M53*O53,0) -> 0 | S53: =IFERROR(Q53/1.14,0) -> 0 | U53: =IFERROR((S53/D53),0) -> 0 | Z53: i | AE53: =IFERROR(VLOOKUP($AC53,SightseeingLists!$C$3:$E$121,2,FALSE),0) -> 0 | AU53: =SUM(AE53,AO53,AQ53) -> 0 | AW53: =SUM($AG53,$AI53,$AK53,$AM53,$AS53)/$E$1 -> 0 | AY53: =SUM($AU53,$AW53) -> 0 | BA53: =IFERROR($AY53/$E$3,0) -> 0
D55: =IFERROR(IF(C55="DBL",2,IF(C55="SGL",1,IF(C55="TPL",3,0))),0) -> 0 | K55: =IFERROR(I55-G55,0) -> 0 | Q55: =IFERROR(K55*M55*O55,0) -> 0 | S55: =IFERROR(Q55/1.14,0) -> 0 | U55: =IFERROR((S55/D55),0) -> 0 | Z55: i | AE55: =IFERROR(VLOOKUP($AC55,SightseeingLists!$C$3:$E$121,2,FALSE),0) -> 0 | AU55: =SUM(AE55,AO55,AQ55) -> 0 | AW55: =SUM($AG55,$AI55,$AK55,$AM55,$AS55)/$E$1 -> 0 | AY55: =SUM($AU55,$AW55) -> 0 | BA55: =IFERROR($AY55/$E$3,0) -> 0
D57: =IFERROR(IF(C57="DBL",2,IF(C57="SGL",1,IF(C57="TPL",3,0))),0) -> 0 | K57: =IFERROR(I57-G57,0) -> 0 | Q57: =IFERROR(K57*M57*O57,0) -> 0 | S57: =IFERROR(Q57/1.14,0) -> 0 | U57: =IFERROR((S57/D57),0) -> 0 | Z57: i | AE57: =IFERROR(VLOOKUP($AC57,SightseeingLists!$C$3:$E$121,2,FALSE),0) -> 0 | AU57: =SUM(AE57,AO57,AQ57) -> 0 | AW57: =SUM($AG57,$AI57,$AK57,$AM57,$AS57)/$E$1 -> 0 | AY57: =SUM($AU57,$AW57) -> 0 | BA57: =IFERROR($AY57/$E$3,0) -> 0
D59: =IFERROR(IF(C59="DBL",2,IF(C59="SGL",1,IF(C59="TPL",3,0))),0) -> 0 | K59: =IFERROR(I59-G59,0) -> 0 | Q59: =IFERROR(K59*M59*O59,0) -> 0 | S59: =IFERROR(Q59/1.14,0) -> 0 | U59: =IFERROR((S59/D59),0) -> 0
D61: =IFERROR(IF(C61="DBL",2,IF(C61="SGL",1,IF(C61="TPL",3,0))),0) -> 0 | K61: =IFERROR(I61-G61,0) -> 0 | Q61: =IFERROR(K61*M61*O61,0) -> 0 | S61: =IFERROR(Q61/1.14,0) -> 0 | U61: =IFERROR((S61/D61),0) -> 0
D63: =IFERROR(IF(C63="DBL",2,IF(C63="SGL",1,IF(C63="TPL",3,0))),0) -> 0 | K63: =IFERROR(I63-G63,0) -> 0 | Q63: =IFERROR(K63*M63*O63,0) -> 0 | S63: =IFERROR(Q63/1.14,0) -> 0 | U63: =IFERROR((S63/D63),0) -> 0
D65: =IFERROR(IF(C65="DBL",2,IF(C65="SGL",1,IF(C65="TPL",3,0))),0) -> 0 | K65: =IFERROR(I65-G65,0) -> 0 | Q65: =IFERROR(K65*M65*O65,0) -> 0 | S65: =IFERROR(Q65/1.14,0) -> 0 | U65: =IFERROR((S65/D65),0) -> 0
D67: =IFERROR(IF(C67="DBL",2,IF(C67="SGL",1,IF(C67="TPL",3,0))),0) -> 0 | K67: =IFERROR(I67-G67,0) -> 0 | Q67: =IFERROR(K67*M67*O67,0) -> 0 | S67: =IFERROR(Q67/1.14,0) -> 0 | U67: =IFERROR((S67/D67),0) -> 0
D69: =IFERROR(IF(C69="DBL",2,IF(C69="SGL",1,IF(C69="TPL",3,0))),0) -> 0 | K69: =IFERROR(I69-G69,0) -> 0 | Q69: =IFERROR(K69*M69*O69,0) -> 0 | S69: =IFERROR(Q69/1.14,0) -> 0 | U69: =IFERROR((S69/D69),0) -> 0
D71: =IFERROR(IF(C71="DBL",2,IF(C71="SGL",1,IF(C71="TPL",3,0))),0) -> 0 | K71: =IFERROR(I71-G71,0) -> 0 | Q71: =IFERROR(K71*M71*O71,0) -> 0 | S71: =IFERROR(Q71/1.14,0) -> 0 | U71: =IFERROR((S71/D71),0) -> 0

Sheet AccommodationLists
A1: DBL
A2: SGL
A3: TPL

Sheet TransportationLists
C1: 1 | D1: 2 | E1: 3 | F1: 4 | G1: 5 | H1: 6 | I1: 7 | J1: 8 | K1: 9 | L1: 10 | M1: 11 | N1: 12
A2: S | B2: Destination | C2: SSH | D2: Sedan | F2: 1*11 | H2: 1*16 | J2: 1*25 | L2: 1*45 | N2: Rep Allowance | O2: Slice | P2: Destination List
D3: Rent | E3: Tip | F3: Rent | G3: Tip | H3: Rent | I3: Tip | J3: Rent | K3: Tip | L3: Rent | M3: Tip | Q3: SSH | R3: HRG | S3: LXR | T3: ASW | U3: RMF | V3: CAI
A4: =ROW()-2 -> 2 | B4: SSH | C4: مطار / فندق | D4: 0 | F4: 480 | H4: =F4*(1+14.5%) -> 549.6 | J4: 780 | K4: 250 | L4: 1800 | N4: 150 | O4: Sedan | P4: SSH | Q4: مطار / فندق | R4: مطار - داخلي | S4: محطة / فندق / العكس | T4: محطة / فندق | U4: مطار - فنادق شمال | V4: مطار / سهرة من وسط البلد / هرم
A5: =ROW()-2 -> 3 | B5: SSH | C5: نصف يومية رأس محمد | D5: 0 | F5: 1350 | H5: =F5*(1+14.5%) -> 1545.75 | J5: 1710 | L5: 3960 | N5: 150 | O5: 1*11 | P5: HRG | Q5: نصف يومية رأس محمد | R5: مطار - الجونة | S5: محطة / فندق / العكس / جنوب المدينة | T5: مطار / فندق | U5: مطار - فنادق شمال - مطار | V5: مطار / سهرة من أكتوبر
A6: =ROW()-2 -> 4 | B6: SSH | C6: يومية كاملة رأس محمد | D6: 0 | F6: 1800 | H6: =F6*(1+14.5%) -> 2061 | J6: 2280 | L6: 4800 | N6: 150 | O6: 1*16 | P6: LXR | Q6: يومية كاملة رأس محمد | R6: مطار - سهل حشيش | S6: توصيلة داخل البلد | T6: محطة / ميناء السد العالي | U6: مطار - فنادق جنوب | V6: نص يوم هرم / بلد من الهرم / وسط البلد
A7: =ROW()-2 -> 5 | B7: SSH | C7: توصيلة سقالة ذهاب و عودة | D7: 0 | F7: 426 | H7: =F7*(1+14.5%) -> 487.77 | J7: 726 | L7: 1632 | N7: 150 | O7: 1*25 | P7: ASW | Q7: توصيلة سقالة ذهاب و عودة | R7: مطار - مكادي | S7: توصيلة داخل البلد / جنوب المدينة | T7: مطار / ميناء السد العالي | U7: مطار - فنادق جنوب - مطار | V7: نص يوم هرم / بلد من أكتوبر
A8: =ROW()-2 -> 6 | B8: SSH | C8: رحلة جمال وادي مندر | D8: 0 | F8: 1704 | H8: =F8*(1+14.5%) -> 1951.08 | J8: 2250 | L8: 4104 | N8: 150 | O8: 1*45 | P8: RMF | Q8: رحلة جمال وادي مندر | R8: مطار- سفاجا | S8: مطار / فندق / العكس | T8: مسلة / سد عالي | U8: مطار - فنادق شمس علم | V8: يومية هرم / بلد من الهرم / وسط البلد
A9: =ROW()-2 -> 7 | B9: SSH | C9: عشاء بدوي وادي خريزة | D9: 0 | F9: 870 | H9: =F9*(1+14.5%) -> 996.15 | J9: 1440 | L9: 2520 | N9: 150 | P9: CAI | Q9: عشاء بدوي وادي خريزة | R9: مطار - نفرتاري | S9: مطار / فندق / العكس / جنوب المدينة | T9: معبد فيلة | U9: مطار - فنادق شمس علم - مطار | V9: يومية هرم / بلد من أكتوبر
A10: =ROW()-2 -> 8 | B10: SSH | C10: جلاس بوت توصيلة | D10: 0 | F10: 426 | H10: 426 | J10: 426 | L10: 1632 | N10: 150 | Q10: جلاس بوت توصيلة | R10: مطار - القصير (حتي أكاسيا) | S10: توصيلة فندق المديرة / العكس | T10: سد عالي / معبد فيلة | U10: فنادق شمال - الغردقة | V10: يومية دهشور من الهرم / وسط البلد
A11: =ROW()-2 -> 9 | B11: SSH | C11: موتوسيكلات توصيلة | D11: 0 | F11: 426 | H11: 426 | J11: 426 | L11: 1632 | N11: 150 | Q11: موتوسيكلات توصيلة | R11: مطار الغرقدة - بورت غالب | S11: مطار فندق المديرة / العكس | T11: مسلة / فيلة | U11: فنادق جنوب - الغردقة | V11: جولة بلد
A12: =ROW()-2 -> 10 | B12: SSH | C12: شرم الشيخ 4 ساعات سيتي تور | D12: 0 | F12: 1323 | H12: 1323 | J12: 1323 | L12: 3238 | N12: 150 | Q12: شرم الشيخ 4 ساعات سيتي تور | R12: مطار الغرقدة - مرسي علم | S12: معبد الأقصر | T12: مسلة / سد عالي / معبد فيلة | U12: القصير (حتي أكاسيا) - الغرقدة | V12: في حالة عشاء مطعم بعد اليومية أو السهرة
A13: =ROW()-2 -> 11 | B13: SSH | C13: شرم الشيخ 8 ساعات سيتي تور | D13: 0 | F13: 1788 | H13: 1788 | J13: 1788 | L13: 4500 | N13: 150 | Q13: شرم الشيخ 8 ساعات سيتي تور | R13: مطار الغردقة - شمس علم | S13: معبد الأقصر / جنوب المدينة | T13: سد عالي / معبد فيلة / معبد كلابشة | U13: فنادق شمال - جولة بلد | V13: مطار / يومية / مطار
A14: =ROW()-2 -> 12 | B14: SSH | C14: شرم - كاترين - شرم | D14: 0 | F14: 3900 | H14: =F14*(1+14.5%) -> 4465.5 | J14: 5526 | L14: 9948 | N14: 150 | Q14: شرم - كاترين - شرم | R14: سفر - وصول مرسي علم شمال | S14: معبد الكرنك | T14: معبد كلابشة | U14: فنادق جنوب - جولة بلد | V14: توصيلة / الإسكندرية
A15: =ROW()-2 -> 13 | B15: SSH | C15: شرم - جبل موسي - شرم | D15: 0 | F15: 3900 | H15: =F15*(1+14.5%) -> 4465.5 | J15: 5526 | L15: 9948 | N15: 150 | Q15: شرم - جبل موسي - شرم | R15: سفر - وصول مرسي علم جنوب | S15: معبد الكرنك / جنوب المدينة | T15: مطار / سد / مسلة | U15: فنادق - رحلة أبو دباب | V15: توصيلة / الفيوم وادي الريان
A16: =ROW()-2 -> 14 | B16: SSH | C16: شرم - دهب توصيلة | D16: 0 | F16: 1632 | H16: =F16*(1+14.5%) -> 1868.64 | J16: 2160 | L16: 4656 | N16: 150 | Q16: شرم - دهب توصيلة | R16: مطار الغردقة - حماطة | S16: المتحف | T16: مطار / سد / فيلة / مسلة | U16: فنادق - شرم اللولي | V16: توصيلة / بورسعيد
A17: =ROW()-2 -> 15 | B17: SSH | C17: شرم - دهب - شرم شوبينج | D17: 0 | F17: 2844 | H17: =F17*(1+14.5%) -> 3256.38 | J17: 3396 | L17: 7344 | N17: 150 | Q17: شرم - دهب - شرم شوبينج | R17: الغردقة / جولة بلد - الف ليلة | S17: المتحف / جنوب المدينة | T17: مطار / معبد فيلة | U17: بحر و عودة - حماطة | V17: توصيلة / الزعفرانة
A18: =ROW()-2 -> 16 | B18: SSH | C18: شرم - نويبع توصيلة | D18: 0 | F18: 2604 | H18: =F18*(1+14.5%) -> 2981.58 | J18: 3600 | L18: 6360 | N18: 150 | Q18: شرم - نويبع توصيلة | R18: الجونة / جولة بلد - الف ليلة | S18: معبد الكرنك / الأقصر | T18: صوت و ضوء فيلة | U18: شلاتين أوفر داي | V18: توصيلة / الساحل حتي بورتو مارينا
A19: =ROW()-2 -> 17 | B19: SSH | C19: شرم - طابا توصيلة | D19: 0 | F19: 3156 | H19: =F19*(1+14.5%) -> 3613.62 | J19: 4656 | L19: 9240 | N19: 150 | Q19: شرم - طابا توصيلة | R19: سهل حشيش / جولة بلد - الف ليلة | S19: معبد الكرنك / الأقصر / جنوب المدينة | T19: المتحف النوبي | U19: الأقصر أوفر داي - شمال مرسي علم | V19: توصيلة / رأس سدر
A20: =ROW()-2 -> 18 | B20: SSH | C20: شرم - طابا - شرم (القدس) | D20: 0 | F20: 4460 | H20: =F20*(1+14.5%) -> 5106.7 | J20: 6630 | L20: 12312 | N20: 150 | Q20: شرم - طابا - شرم (القدس) | R20: مكادي / جولة بلد - الف ليلة | S20: الصوت و الضوء | T20: يوم بلد (8 ساعات) | U20: الأقصر أوفر داي - جنوب مرسي علم | V20: توصيلة / السويس
A21: =ROW()-2 -> 19 | B21: SSH | C21: شرم - القاهرة (توصيلة) | D21: 0 | F21: 6906 | H21: =F21*(1+14.5%) -> 7907.37 | J21: 11352 | L21: 18156 | N21: 150 | Q21: شرم - القاهرة (توصيلة) | R21: سفاجا أو سوما باي / جولة بلد - الف ليلة | S21: الصوت و الضوء / جنوب المدينة | T21: سهرة أو عشاء بالبلد | U21: أسوان أوفر داي | V21: توصيلة / السخنة
A22: =ROW()-2 -> 20 | B22: SSH | C22: شرم - القاهرة - شرم (أوفر داي) | D22: 0 | F22: 9474 | H22: =F22*(1+14.5%) -> 10847.73 | J22: 14130 | L22: 22104 | N22: 150 | Q22: شرم - القاهرة - شرم (أوفر داي) | R22: الغردقة / بحر و عودة | S22: متحف / صوت و ضوء | T22: جولة بلد | U22: أسوان أوفر نايت + أبو سمبل | V22: توصيلة / الإسماعيلية
A23: =ROW()-2 -> 21 | B23: SSH | C23: شرم - القاهرة - شرم (أوفر نايت) | D23: 0 | F23: 11130 | H23: =F23*(1+14.5%) -> 12743.85 | J23: 16578 | L23: 25200 | N23: 150 | Q23: شرم - القاهرة - شرم (أوفر نايت) | R23: الجونة / بحر و عودة | S23: متحف / صوت و ضوء / جنوب المدينة | T23: دراو | U23: رحلة وادي الجمال و العودة | V23: توصيلة / المنصورة
A24: =ROW()-2 -> 22 | B24: SSH | C24: طابا - كاترين - طابا | D24: 0 | F24: 5448 | H24: =F24*(1+14.5%) -> 6237.96 | J24: 7452 | L24: 14076 | N24: 150 | Q24: طابا - كاترين - طابا | R24: سهل حشيش / بحر و عودة | S24: غرب يوم كامل | T24: كوم أمبو (توصيلة) | U24: توصيلة الأقصر من شمال مرسي علم | V24: توصيلة / المحلة
A25: =ROW()-2 -> 23 | B25: SSH | C25: ليلة مبيت | D25: 0 | F25: 828 | H25: =F25*(1+14.5%) -> 948.06 | J25: 1242 | L25: 2556 | N25: 150 | Q25: ليلة مبيت | R25: مكادي / بحر و عودة | S25: البر الغربي | T25: كوم أمبو / إدفو (أوفر داي) | U25: توصيلة الأقصر من جنوب مرسي علم | V25: توصيلة / الساحل بعد بورتو مارينا
A26: =ROW()-2 -> 24 | B26: SSH | C26: سفاري دهب | D26: 0 | F26: 0 | H26: 0 | J26: 0 | L26: 0 | N26: 150 | Q26: سفاري دهب | R26: سفاجا أو سوما باي / بحر و عودة | S26: دندرة | T26: إدفو (توصيلة) | U26: توصيلة أسوان | V26: توصيلة / مطروح
A27: =ROW()-2 -> 25 | B27: SSH | C27: نصف يوم سفاري منجروف | D27: 0 | F27: 0 | H27: 0 | J27: 0 | L27: 0 | N27: 150 | Q27: نصف يوم سفاري منجروف | R27: شرم الناقة | S27: دندرة / أبيدوس | T27: الكاب (أوفر داي) | U27: ليلة مبيت | V27: توصيلة / الغردقة
A28: =ROW()-2 -> 26 | B28: SSH | C28: سفاري منجروف | D28: 0 | F28: 0 | H28: 0 | J28: 0 | L28: 0 | N28: 150 | Q28: سفاري منجروف | R28: توصيلة أسوان | S28: إسنا | T28: الأقصر (توصيلة أو زيارات) | V28: توصيلة / شرم الشيخ
A29: =ROW()-2 -> 27 | B29: SSH | C29: سوبر سفاري | D29: 0 | F29: 0 | H29: 0 | J29: 0 | L29: 0 | N29: 150 | Q29: سوبر سفاري | R29: توصيلة الأقصر | S29: إدفو / العودة | T29: أسوان / مرسي علم / البلد | V29: يومية / الإسكندرية
A30: =ROW()-2 -> 28 | B30: SSH | C30: كانيون | D30: 0 | F30: 0 | H30: 0 | J30: 0 | L30: 0 | N30: 150 | Q30: كانيون | R30: توصيلة القاهرة | S30: إدفو / كوم أمبو / العودة | T30: سفاجا توصيلة | V30: يومية / الفيوم وادي الريان
A31: =ROW()-2 -> 29 | B31: HRG | C31: مطار - داخلي | D31: 430 | E31: 60 | F31: 515 | G31: 70 | H31: 515 | I31: 70 | J31: 860 | K31: 85 | L31: 1625 | M31: 110 | N31: 150 | R31: أوفر داي الأقصر | S31: أسوان توصيلة أو زيارات | T31: الغردقة (توصيلة) | V31: يومية / بورسعيد
A32: =ROW()-2 -> 30 | B32: HRG | C32: مطار - الجونة | D32: 545 | E32: 65 | F32: 605 | G32: 80 | H32: 605 | I32: 80 | J32: 1110 | K32: 105 | L32: 2065 | M32: 130 | N32: 150 | R32: أوفر داي الأديرة - الزعفرانة | S32: القصير | T32: أبو سمبل و العودة في نفس اليوم | V32: يومية / الزعفرانة
A33: =ROW()-2 -> 31 | B33: HRG | C33: مطار - سهل حشيش | D33: 545 | E33: 65 | F33: 605 | G33: 100 | H33: 605 | I33: 80 | J33: 1110 | K33: 105 | L33: 2065 | M33: 130 | N33: 150 | R33: أوفر داي القاهرة | S33: سفاجا | T33: أبو سمبل و العودة في اليوم التالي | V33: يومية / الساحل حتي بورتو مارينا
A34: =ROW()-2 -> 32 | B34: HRG | C34: مطار - مكادي | D34: 580 | E34: 65 | F34: 655 | G34: 80 | H34: 655 | I34: 80 | J34: 1185 | K34: 105 | L34: 230 | M34: 130 | N34: 150 | R34: دندرة و أبيدوس | S34: سفاجا / الأقصر بالزيارات مع مبيت و عوده | T34: دير الأنبا هدرا | V34: يومية / رأس سدر
A35: =ROW()-2 -> 33 | B35: HRG | C35: مطار- سفاجا | D35: 780 | E35: 80 | F35: 860 | G35: 85 | H35: 860 | I35: 85 | J35: 1360 | K35: 135 | L35: 2710 | M35: 170 | N35: 150 | R35: أوفر داي أسوان | S35: الغردقة | T35: مقابر النبلاء | V35: يومية / السويس
A36: =ROW()-2 -> 34 | B36: HRG | C36: مطار - نفرتاري | D36: 1275 | E36: 105 | F36: 1415 | G36: 110 | H36: 1415 | I36: 110 | J36: 2095 | K36: 155 | L36: 4310 | M36: 220 | N36: 150 | R36: أوفر نايت الإسكندرية | S36: غرب + شرق + غردقة | T36: غرب سهيل | V36: يومية / السخنة
A37: =ROW()-2 -> 35 | B37: HRG | C37: مطار - القصير (حتي أكاسيا) | D37: 1710 | E37: 145 | F37: 1920 | G37: 170 | H37: 1920 | I37: 170 | J37: 2960 | K37: 220 | L37: 4925 | M37: 255 | N37: 150 | R37: ليلة مبيت مع مبيت للسائق | S37: مرسي علم | T37: غرب سهيل / زيارة | V37: يومية / الإسماعيلية
A38: =ROW()-2 -> 36 | B38: HRG | C38: مطار الغرقدة - بورت غالب | D38: 2440 | E38: 195 | F38: 2710 | G38: 220 | H38: 2710 | I38: 220 | J38: 3690 | K38: 275 | L38: 7640 | M38: 495 | N38: 150 | S38: القاهرة | V38: يومية / المنصورة
A39: =ROW()-2 -> 37 | B39: HRG | C39: مطار الغرقدة - مرسي علم | D39: 2880 | E39: 240 | F39: 3205 | G39: 275 | H39: 3205 | I39: 275 | J39: 4195 | K39: 325 | L39: 8640 | M39: 565 | N39: 150 | S39: سهرة عشاء البلد | V39: يومية / المحلة
A40: =ROW()-2 -> 38 | B40: HRG | C40: مطار الغردقة - شمس علم | D40: 3330 | E40: 300 | F40: 3690 | G40: 325 | H40: 3690 | I40: 325 | J40: 4705 | K40: 395 | L40: 9855 | M40: 970 | N40: 150 | S40: سهرة عشاء بالغرب | V40: القاهرة / دهب
...

Sheet SightseeingLists
C1: 1 | D1: 2 | E1: 3 | G1: Destinations | I1: Cairo | J1: Alexandria | K1: Luxor | L1: Aswan | M1: Giza
A2: S | B2: Destination | C2: Sight | D2: Price | E2: Rep | G2: Alexandria | I2: قلعة صلاح الدين الأيوبي | J2: مقابر مصطفى كامل | K2: معبد الطود | L2: دير الأنبا سمعان | M2: منطقة أهرامات الجيزة
A3: =ROW()-2 -> 1 | B3: Cairo | C3: قلعة صلاح الدين الأيوبي | D3: 450 | E3: 50 | G3: Aswan | I3: بانوراما قصر البارون | J3: مقابر الأنفوشي | K3: معبد المعلا | L3: معابد أبو سمبل | M3: هرم خوفو من الداخل
A4: =ROW()-2 -> 2 | B4: Cairo | C4: بانوراما قصر البارون | D4: 120 | G4: Cairo | I4: مدرسة السلطان حسن وجامع الرفاعي | J4: مقابر الشاطبي | K4: معابد الكرنك (التذكرة تشمل زيارة طريق الكباش) | L4: معبد أبو سمبل إحتفالية تعامد الشمس ٢٢ أكتوبر/٢٢ فبراير | M4: هرم خفرع (أهرامات الجيزة)
A5: =ROW()-2 -> 3 | B5: Cairo | C5: مدرسة السلطان حسن وجامع الرفاعي | D5: 180 | G5: Giza | I5: منزل السحيمي | J5: متحف السويس القومي | K5: معبد موت بالكرنك | L5: معابد فيلة | M5: هرم منكاورع (أهرامات الجيزة
A6: =ROW()-2 -> 4 | B6: Cairo | C6: منزل السحيمي | D6: 180 | G6: Luxor | I6: باب زويلة | J6: متحف الإسماعيلية | K6: معبد الأقصر (التذكرة تشمل زيارة طريق الكباش) | L6: بانوراما معابد فيلة | M6: أبو الهول (زيارات خاصة فقط) رسوم فتح الموقع
A7: =ROW()-2 -> 5 | B7: Cairo | C7: باب زويلة | D7: 100 | I7: مجموعة محمد بك أبو الدهب (متحف نجيب محفوظ) | J7: معبد الوحي بسيوة | K7: وادي الملوك | L7: معبد إدفو | M7: مقبرة مر- اس -عنخ
A8: =ROW()-2 -> 6 | B8: Cairo | C8: مجموعة محمد بك أبو الدهب (متحف نجيب محفوظ) | D8: 100 | I8: التكية المولوية | J8: جبل الموتى بسيوة | K8: مقبرة ستي الأول | L8: معبد كوم امبو | M8: مقابر العمال
A9: =ROW()-2 -> 7 | B9: Cairo | C9: التكية المولوية | D9: 100 | I9: سبيل وكتاب محمد علي بالعقادين | J9: متحف مطروح | K9: مقبرة آي | L9: قبة الهوا | M9: منطقة سقارة ومتحف إيمحتب (تشمل زيارة مجموعة الهرم المدرج للملك زوسر، أهرامات تتي وأوناس ،كاجمني نكاواسسي، عنخ ماحور، نفر، سشم بتاح،بتاح حتب، تي، إيدوت، أوناس عنخ، إينفرت)
A10: =ROW()-2 -> 8 | B10: Cairo | C10: سبيل وكتاب محمد علي بالعقادين | D10: 60 | I10: مجموعة الغوري القبة والسبيل والمنزل | J10: متحف كهف روميل | K10: الدير البحري (حتشبسوت) | L10: جزيرة الفنتين | M10: مقابر النبلاء، مقابر الدولة الحديثة بجبانة حور محب والبوباسطين
A11: =ROW()-2 -> 9 | B11: Cairo | C11: مجموعة الغوري القبة والسبيل والمنزل | D11: 150 | I11: وكالة الغوري | J11: آثار مدينة رشيد | K11: دير المدينة | L11: المسلة الناقصة | M11: المقبرة الجنوبية
A12: =ROW()-2 -> 10 | B12: Cairo | C12: وكالة الغوري | D12: 100 | I12: منزل علي لبيب | J12: قلعة قايتباي | K12: مقبرة باشدو | L12: معابد كلابشة | M12: تذاكر مجمعة لجميع مقابر سقارة
A13: =ROW()-2 -> 11 | B13: Cairo | C13: منزل علي لبيب | D13: 100 | I13: منزل الهراوي | J13: كوم الشقافة | K13: مقبرة رعموزا | L13: الكاب | M13: هرم زوسر المدرج من المدخل الجنوبي (سقارة)
A14: =ROW()-2 -> 12 | B14: Cairo | C14: منزل الهراوي | D14: 100 | I14: سييل وكتاب قايتباي شارع الصليبة | J14: كوم الدكة (المسرح الروماني) | K14: معبد الرامسيوم | L14: معبد عمدا | M14: السرابيوم (سقارة)
A15: =ROW()-2 -> 13 | B15: Cairo | C15: سييل وكتاب قايتباي شارع الصليبة | D15: 100 | I15: منزل الست وسيلة | J15: عمود السواري | K15: علوة عبد القرنة | L15: معبد وادي السبوع | M15: مقبرة مريروكا (سقارة)
A16: =ROW()-2 -> 14 | B16: Cairo | C16: منزل الست وسيلة | D16: 100 | I16: سبيل نفيسه البيضا | J16: الآثار الغارقة بالميناء الشرقي (المتحف المغمور) | K16: بيت كارتر ونسخة من مقبرة توت عنخ آمون | L16: جزيرة سهيل | M16: منطقة دهشور
A17: =ROW()-2 -> 15 | B17: Cairo | C17: سبيل نفيسه البيضا | D17: 60 | I17: قصر محمد علي بشبرا (الافتتاح قريبا) | J17: متحف الإسكندرية القومي | K17: مقبرة مننا ونخت | L17: جبل السلسلة | M17: منطقة ميت رهينة
A18: =ROW()-2 -> 16 | B18: Cairo | C18: قصر محمد علي بشبرا (الافتتاح قريبا) | D18: 240 | I18: شجرة مريم | J18: متحف المجوهرات الملكية | K18: معبد ستي الأول | L18: معبد إيزيس
A19: =ROW()-2 -> 17 | B19: Cairo | C19: شجرة مريم | D19: 100 | I19: مسلة سنوسرت الأول بالمطرية | J19: المتحف اليوناني الروماني (عند الافتتاح) | K19: مقبرة أوسرحات وخنسو | L19: متحف النوبة
A20: =ROW()-2 -> 18 | B20: Cairo | C20: مسلة سنوسرت الأول بالمطرية | D20: 150 | I20: المتحف المصري بالتحرير | K20: العساسيف
A21: =ROW()-2 -> 19 | B21: Cairo | C21: المتحف المصري بالتحرير | D21: 450 | I21: المرشد السمعي ( المجموعات) التحف الصري | K21: معبد إسنا
A22: =ROW()-2 -> 20 | B22: Cairo | C22: المرشد السمعي ( المجموعات) التحف الصري | D22: 50 | I22: متحق الفن الإسلامي | K22: مقبرة توت عنخ آمون (وادي الملوك)
A23: =ROW()-2 -> 21 | B23: Cairo | C23: متحق الفن الإسلامي | D23: 270 | I23: المتحف القبطي | K23: مقبرة رمسيس السادس (وادي الملوك)
A24: =ROW()-2 -> 22 | B24: Cairo | C24: المتحف القبطي | D24: 230 | I24: متحف المطار 2 و 3 | K24: معبد هابو
A25: =ROW()-2 -> 23 | B25: Cairo | C25: متحف المطار 2 و 3 | D25: =8*32 -> 256 | I25: متحف المركبات اللكية | K25: وادي الملكات
A26: =ROW()-2 -> 24 | B26: Cairo | C26: متحف المركبات اللكية | D26: 240 | I26: قصر البارون | K26: مقبرة نفرتاري (وادي الملكات)
A27: =ROW()-2 -> 25 | B27: Cairo | C27: قصر البارون | D27: 180 | I27: شارع المعز | K27: مقبرة باباسا
A28: =ROW()-2 -> 26 | B28: Cairo | C28: شارع المعز | D28: 180 | I28: قصر محمد علي بالمنيل | K28: مقابر الخوخة
A29: =ROW()-2 -> 27 | B29: Cairo | C29: قصر محمد علي بالمنيل | D29: 180 | I29: مقياس النيل | K29: مقابر روي وشروي
A30: =ROW()-2 -> 28 | B30: Cairo | C30: مقياس النيل | D30: 100 | K30: معبد إيزيس ودير شلويط
A31: =ROW()-2 -> 29 | B31: Giza | C31: منطقة أهرامات الجيزة | D31: 540 | K31: جبانة قرنة مرمي
A32: =ROW()-2 -> 30 | B32: Giza | C32: هرم خوفو من الداخل | D32: 900 | K32: جبانة الشيخ عبد القرنة
A33: =ROW()-2 -> 31 | B33: Giza | C33: هرم خفرع (أهرامات الجيزة) | D33: 220 | K33: معبد مرنبتاح
A34: =ROW()-2 -> 32 | B34: Giza | C34: هرم منكاورع (أهرامات الجيزة | D34: 220 | K34: متحف التحنيط
A35: =ROW()-2 -> 33 | B35: Giza | C35: أبو الهول (زيارات خاصة فقط) رسوم فتح الموقع | D35: 200 | K35: متحف الأقصر
A36: =ROW()-2 -> 34 | B36: Giza | C36: مقبرة مر- اس -عنخ | D36: 120 | K36: المرشد السمعي متحف الأقصر
A37: =ROW()-2 -> 35 | B37: Giza | C37: مقابر العمال | D37: 700 | K37: معبد ستي الأول (أبيدوس)
A38: =ROW()-2 -> 36 | B38: Giza | C38: منطقة سقارة ومتحف إيمحتب (تشمل زيارة مجموعة الهرم المدرج للملك زوسر، أهرامات تتي وأوناس ،كاجمني نكاواسسي، عنخ ماحور، نفر، سشم بتاح،بتاح حتب، تي، إيدوت، أوناس عنخ، إينفرت) | D38: 450 | K38: قصر الأمير يوسف كمال
A39: =ROW()-2 -> 37 | B39: Giza | C39: مقابر النبلاء، مقابر الدولة الحديثة بجبانة حور محب والبوباسطين | D39: 330 | K39: بانوراما معبد دندرة
A40: =ROW()-2 -> 38 | B40: Giza | C40: المقبرة الجنوبية | D40: 240 | K40: معبد دندرة
...

Sheet GPT cache
